933
Traceback (most recent call last):
  File "<string>", line 1, in <module>
  File "C:\Users\akisl\new_anaconda3\envs\icr-env\lib\multiprocessing\spawn.py", line 116, in spawn_main
    exitcode = _main(fd, parent_sentinel)
  File "C:\Users\akisl\new_anaconda3\envs\icr-env\lib\multiprocessing\spawn.py", line 125, in _main
    prepare(preparation_data)
  File "C:\Users\akisl\new_anaconda3\envs\icr-env\lib\multiprocessing\spawn.py", line 236, in prepare
    _fixup_main_from_path(data['init_main_from_path'])
  File "C:\Users\akisl\new_anaconda3\envs\icr-env\lib\multiprocessing\spawn.py", line 287, in _fixup_main_from_path
    main_content = runpy.run_path(main_path,
  File "C:\Users\akisl\new_anaconda3\envs\icr-env\lib\runpy.py", line 288, in run_path
    return _run_module_code(code, init_globals, run_name,
  File "C:\Users\akisl\new_anaconda3\envs\icr-env\lib\runpy.py", line 97, in _run_module_code
    _run_code(code, mod_globals, init_globals,
  File "C:\Users\akisl\new_anaconda3\envs\icr-env\lib\runpy.py", line 87, in _run_code
    exec(code, run_globals)
  File "C:\Users\akisl\Desktop\self\FACT-UvA-2024\scripts\run_experiments.py", line 26, in <module>
    os.mkdir(savepath + f"_{id}/")
FileNotFoundError: [WinError 3] The system cannot find the path specified: '../experiments/remote-experiments/test_generic/greenfield/_933/'
322
Traceback (most recent call last):
  File "<string>", line 1, in <module>
  File "C:\Users\akisl\new_anaconda3\envs\icr-env\lib\multiprocessing\spawn.py", line 116, in spawn_main
    exitcode = _main(fd, parent_sentinel)
  File "C:\Users\akisl\new_anaconda3\envs\icr-env\lib\multiprocessing\spawn.py", line 125, in _main
    prepare(preparation_data)
  File "C:\Users\akisl\new_anaconda3\envs\icr-env\lib\multiprocessing\spawn.py", line 236, in prepare
    _fixup_main_from_path(data['init_main_from_path'])
  File "C:\Users\akisl\new_anaconda3\envs\icr-env\lib\multiprocessing\spawn.py", line 287, in _fixup_main_from_path
    main_content = runpy.run_path(main_path,
  File "C:\Users\akisl\new_anaconda3\envs\icr-env\lib\runpy.py", line 288, in run_path
    return _run_module_code(code, init_globals, run_name,
  File "C:\Users\akisl\new_anaconda3\envs\icr-env\lib\runpy.py", line 97, in _run_module_code
    _run_code(code, mod_globals, init_globals,
  File "C:\Users\akisl\new_anaconda3\envs\icr-env\lib\runpy.py", line 87, in _run_code
    exec(code, run_globals)
  File "C:\Users\akisl\Desktop\self\FACT-UvA-2024\scripts\run_experiments.py", line 26, in <module>
    os.mkdir(savepath + f"_{id}/")
FileNotFoundError: [WinError 3] The system cannot find the path specified: '../experiments/remote-experiments/test_generic/greenfield/_322/'
332
Traceback (most recent call last):
  File "<string>", line 1, in <module>
  File "C:\Users\akisl\new_anaconda3\envs\icr-env\lib\multiprocessing\spawn.py", line 116, in spawn_main
    exitcode = _main(fd, parent_sentinel)
  File "C:\Users\akisl\new_anaconda3\envs\icr-env\lib\multiprocessing\spawn.py", line 125, in _main
    prepare(preparation_data)
  File "C:\Users\akisl\new_anaconda3\envs\icr-env\lib\multiprocessing\spawn.py", line 236, in prepare
    _fixup_main_from_path(data['init_main_from_path'])
  File "C:\Users\akisl\new_anaconda3\envs\icr-env\lib\multiprocessing\spawn.py", line 287, in _fixup_main_from_path
    main_content = runpy.run_path(main_path,
  File "C:\Users\akisl\new_anaconda3\envs\icr-env\lib\runpy.py", line 288, in run_path
    return _run_module_code(code, init_globals, run_name,
  File "C:\Users\akisl\new_anaconda3\envs\icr-env\lib\runpy.py", line 97, in _run_module_code
    _run_code(code, mod_globals, init_globals,
  File "C:\Users\akisl\new_anaconda3\envs\icr-env\lib\runpy.py", line 87, in _run_code
    exec(code, run_globals)
  File "C:\Users\akisl\Desktop\self\FACT-UvA-2024\scripts\run_experiments.py", line 26, in <module>
    os.mkdir(savepath + f"_{id}/")
FileNotFoundError: [WinError 3] The system cannot find the path specified: '../experiments/remote-experiments/test_generic/greenfield/_332/'
22
Traceback (most recent call last):
  File "<string>", line 1, in <module>
  File "C:\Users\akisl\new_anaconda3\envs\icr-env\lib\multiprocessing\spawn.py", line 116, in spawn_main
    exitcode = _main(fd, parent_sentinel)
  File "C:\Users\akisl\new_anaconda3\envs\icr-env\lib\multiprocessing\spawn.py", line 125, in _main
    prepare(preparation_data)
  File "C:\Users\akisl\new_anaconda3\envs\icr-env\lib\multiprocessing\spawn.py", line 236, in prepare
    _fixup_main_from_path(data['init_main_from_path'])
  File "C:\Users\akisl\new_anaconda3\envs\icr-env\lib\multiprocessing\spawn.py", line 287, in _fixup_main_from_path
    main_content = runpy.run_path(main_path,
  File "C:\Users\akisl\new_anaconda3\envs\icr-env\lib\runpy.py", line 288, in run_path
    return _run_module_code(code, init_globals, run_name,
  File "C:\Users\akisl\new_anaconda3\envs\icr-env\lib\runpy.py", line 97, in _run_module_code
    _run_code(code, mod_globals, init_globals,
  File "C:\Users\akisl\new_anaconda3\envs\icr-env\lib\runpy.py", line 87, in _run_code
    exec(code, run_globals)
  File "C:\Users\akisl\Desktop\self\FACT-UvA-2024\scripts\run_experiments.py", line 26, in <module>
    os.mkdir(savepath + f"_{id}/")
FileNotFoundError: [WinError 3] The system cannot find the path specified: '../experiments/remote-experiments/test_generic/greenfield/_22/'
953
Traceback (most recent call last):
  File "<string>", line 1, in <module>
  File "C:\Users\akisl\new_anaconda3\envs\icr-env\lib\multiprocessing\spawn.py", line 116, in spawn_main
    exitcode = _main(fd, parent_sentinel)
  File "C:\Users\akisl\new_anaconda3\envs\icr-env\lib\multiprocessing\spawn.py", line 125, in _main
    prepare(preparation_data)
  File "C:\Users\akisl\new_anaconda3\envs\icr-env\lib\multiprocessing\spawn.py", line 236, in prepare
    _fixup_main_from_path(data['init_main_from_path'])
  File "C:\Users\akisl\new_anaconda3\envs\icr-env\lib\multiprocessing\spawn.py", line 287, in _fixup_main_from_path
    main_content = runpy.run_path(main_path,
  File "C:\Users\akisl\new_anaconda3\envs\icr-env\lib\runpy.py", line 288, in run_path
    return _run_module_code(code, init_globals, run_name,
  File "C:\Users\akisl\new_anaconda3\envs\icr-env\lib\runpy.py", line 97, in _run_module_code
    _run_code(code, mod_globals, init_globals,
  File "C:\Users\akisl\new_anaconda3\envs\icr-env\lib\runpy.py", line 87, in _run_code
    exec(code, run_globals)
  File "C:\Users\akisl\Desktop\self\FACT-UvA-2024\scripts\run_experiments.py", line 26, in <module>
    os.mkdir(savepath + f"_{id}/")
FileNotFoundError: [WinError 3] The system cannot find the path specified: '../experiments/remote-experiments/test_generic/greenfield/_953/'
